Workbook

Sheet Instrucciones de uso
A1: INSTRUCCIONES DE USO Y DILIGENCIAMIENTO · HERRAMIENTA CF1
A2: Programa 22230071_v1 · Componente formativo 1 · Alistamiento y validación de datos de precipitación. Esta guía está dirigida al aprendiz y debe leerse antes de modificar las hojas 1, 2 y 3.
A5: 1. PROPÓSITO FORMATIVO
A6: Organizar, documentar y validar información histórica y proyectada de precipitación para que pueda utilizarse de manera trazable en análisis posteriores. Al finalizar, el aprendiz debe diferenciar dato de entrada, fórmula, alerta y ejemplo; reconocer vacíos, duplicados, unidades incompatibles y registros sin fuente; y presentar una base apta para continuar con el componente formativo 2.
A9: 2. ANTES DE EMPEZAR
A10: 1 | B10: Defina el área de estudio, el área de captación, el municipio, las coordenadas y el sistema de referencia. | G10: 4 | H10: Disponga de proyecciones con escenario SSP, horizonte, modelo o producto, fuente y unidad claramente identificados.
A11: 2 | B11: Seleccione fuentes oficiales o técnicamente trazables y conserve URL, producto, versión, periodo y fecha de consulta. | G11: 5 | H11: Guarde una copia del archivo original y trabaje sobre una versión identificada con su nombre, ficha y fecha.
A12: 3 | B12: Disponga de una serie mensual histórica suficientemente continua; para el ejercicio se espera una referencia de 30 años. | G12: 6 | H12: Recuerde: una celda vacía significa dato ausente; el valor cero significa ausencia medida de precipitación. No son equivalentes.
A14: 3. CÓDIGO DE COLORES
A15: ENTRADA | D15: FÓRMULA | G15: ALERTA | J15: EJEMPLO
A16: Diligencie o reemplace datos | D16: Resultado automático; no sobrescribir | G16: Revise antes de avanzar | J16: Dato demostrativo; sustituir
A18: 4. RUTA DE DILIGENCIAMIENTO
A19: Paso | B19: Pestaña / bloque | D19: Acción del aprendiz | G19: Dónde diligenciar | J19: Control antes de continuar
A20: 1 | B20: Hoja 1 · Área y fuentes | D20: Reemplace la identificación del caso didáctico y registre la localización, el área de captación y los metadatos espaciales. | G20: Celdas azules de los bloques LOCALIZACIÓN y METADATO ESPACIAL. | J20: Los datos describen el mismo sitio y las unidades corresponden a cada encabezado.
A21: 2 | B21: Hoja 1 · Fuentes y trazabilidad | D21: Registre cada estación, producto o fuente; actualice el diccionario de variables y anote decisiones en la bitácora. | G21: Filas azules de FUENTES, DICCIONARIO y BITÁCORA. | J21: Toda serie tiene código, periodo, frecuencia, unidad, versión, fuente, fecha y limitaciones.
A22: 3 | B22: Hoja 2 · Histórico | D22: Pegue la serie mensual en los campos de entrada. Conserve fechas ordenadas, unidad mm y una observación por fila. | G22: Solo columnas azules: Fecha, precipitación, unidad, calidad y observaciones. No pegue sobre columnas verdes. | J22: No hay fechas duplicadas, valores negativos ni meses faltantes sin documentar; el estado de control queda APTA.
A23: 4 | B23: Hoja 3 · Proyecciones | D23: Registre escenario, horizonte, año, mes, precipitación proyectada, unidad, modelo, fuente y observaciones. | G23: Solo columnas azules. Las columnas verdes calculan referencia histórica y cambios absoluto y porcentual. | J23: Cada proyección conserva escenario, horizonte, modelo y fuente; no hay valores negativos y el estado queda APTA.
A24: 5 | B24: Gráficos y producto | D24: Revise tendencias históricas, comportamiento mensual y signo del cambio proyectado. Redacte una interpretación breve basada en los datos. | G24: Gráficos y resúmenes de las hojas 2 y 3; evidencia complementaria del aprendiz. | J24: Los gráficos responden a los datos cargados y la interpretación menciona periodo, fuente, unidades, incertidumbres y limitaciones.
A26: 5. REGLAS CRÍTICAS Y ERRORES FRECUENTES
A27: 1 | B27: No escriba unidades dentro de las celdas numéricas; utilice la unidad indicada en el encabezado. | G27: 4 | H27: No complete vacíos con cero sin evidencia. Registre el faltante, la decisión adoptada y su efecto.
A28: 2 | B28: No mezcle datos diarios, mensuales y anuales sin documentar el procedimiento de agregación. | G28: 5 | H28: No interprete una proyección como pronóstico exacto; compare escenarios y declare la fuente y la incertidumbre.
A29: 3 | B29: No sobrescriba celdas verdes: contienen fórmulas que garantizan la articulación entre hojas. | G29: 6 | H29: Sustituya todos los datos demostrativos antes de utilizar el libro en un estudio o recomendación técnica.
A31: 6. PRODUCTO ESPERADO DEL APRENDIZ
A32: Entregue el libro con: (1) ficha del área y fuentes completas; (2) serie histórica mensual validada; (3) base de proyecciones con escenario, horizonte, modelo y fuente; (4) diccionario y bitácora actualizados; (5) gráficos revisados; y (6) una interpretación breve que describa hallazgos, controles aplicados, incertidumbres y limitaciones. Nombre sugerido: CF1_Apellidos_Nombre_Ficha_Fecha.xlsx.
A36: 7. LISTA DE VERIFICACIÓN ANTES DE ENTREGAR
A37: ☐ | B37: Reemplacé los datos de ejemplo e identifiqué claramente el área de estudio y el área de captación.
A38: ☐ | B38: Registré fuente, versión, periodo, frecuencia, unidad, fecha de consulta y limitaciones de cada conjunto de datos.
A39: ☐ | B39: La serie histórica está ordenada, sin duplicados ni valores negativos, y los vacíos están documentados.
A40: ☐ | B40: Las proyecciones incluyen escenario SSP, horizonte, modelo o producto, fuente y unidad.
A41: ☐ | B41: No sobrescribí fórmulas y revisé las alertas hasta obtener un estado apto o justificar la novedad.
A42: ☐ | B42: Actualicé la bitácora, revisé los gráficos y redacté una interpretación coherente con los resultados.
A44: IMPORTANTE: los datos precargados son exclusivamente didácticos. La calidad del análisis depende de la trazabilidad, consistencia temporal, unidad, cobertura y representatividad de los datos que incorpore el aprendiz.

Sheet Hoja 1 - Área y fuentes
A1: HERRAMIENTA CF1 · ALISTAMIENTO Y VALIDACIÓN DE DATOS DE PRECIPITACIÓN
A2: Programa 22230071_v1 · RA1 · Registre el área, documente las fuentes y conserve la trazabilidad. Los datos precargados son exclusivamente demostrativos y deben sustituirse por información verificable.
A4: LEYENDA | B4: Entrada | C4: Fórmula | D4: Alerta | E4: Ejemplo | F4: Unidades en encabezado
A6: HOJA 1 · LOCALIZACIÓN DEL ÁREA DE ESTUDIO
A7: Campo | B7: Valor | D7: Metadato espacial | E7: Valor | G7: Criterio de trazabilidad: cada dato debe responder qué variable representa, de dónde proviene, qué intervalo y área describe, en qué unidad está, qué tratamiento recibió y qué limitación condiciona su uso.
A8: Identificador del estudio | B8: CASO-DID-001 | D8: Sistema de referencia | E8: MAGNA-SIRGAS / WGS84
A9: Nombre del área | B9: Caso didáctico — reemplazar | D9: Cobertura espacial | E9: Punto / polígono del caso
A10: Municipio | B10: Municipio de ejemplo | D10: Responsable del registro | E10: Aprendiz
A11: Departamento | B11: Departamento de ejemplo | D11: Fecha de actualización | E11: 46250
A12: Latitud (°) | B12: 4.7
A13: Longitud (°) | B13: -74.1
A14: Altitud (m s. n. m.) | B14: 2600
A15: Área de estudio (km²) | B15: 1
A16: Área de captación prevista (m²) | B16: 250
A18: REGISTRO DE ESTACIONES, PRODUCTOS Y FUENTES CLIMÁTICAS
A19: ID | B19: Tipo de fuente | C19: Estación / producto | D19: Código | E19: Latitud | F19: Longitud | G19: Altitud (m) | H19: Periodo disponible | I19: Frecuencia | J19: Variable | K19: Unidad | L19: Resolución / versión | M19: Fuente o URL | N19: Fecha consulta | O19: Limitaciones / observaciones
A20: F-01 | B20: Ejemplo didáctico | C20: Serie sintética de capacitación | D20: DID-001 | E20: 4.7 | F20: -74.1 | G20: 2600 | H20: 1981-2010 | I20: Mensual | J20: Precipitación | K20: mm | L20: v1 demostrativa | M20: Sustituir por IDEAM u otra fuente oficial | N20: 46250 | O20: No usar para estudios reales
A21: F-02 | B21: Fuente oficial | C21: Registrar fuente de contraste | J21: Precipitación | K21: mm | O21: Pendiente de diligenciamiento
A22: F-03
A23: F-04
A26: DICCIONARIO DE VARIABLES | I26: BITÁCORA DE CONTROL Y DECISIONES
A27: Variable | B27: Hoja | C27: Definición / función | D27: Tipo | E27: Unidad / formato | F27: Regla de control | G27: Obligatorio | I27: Fecha | J27: Responsable | K27: Hoja | L27: Acción | M27: Registros | N27: Hallazgo / decisión | O27: Evidencia
A28: Fecha | B28: Hoja 2 | C28: Mes al que corresponde el registro histórico. | D28: Fecha | E28: yyyy-mm-dd | F28: Sin duplicados; secuencia mensual | G28: Sí | I28: 46250 | J28: Aprendiz | K28: Hojas 1-3 | L28: Carga de ejemplo | M28: 552 | N28: Serie y proyecciones demostrativas; sustituir antes de uso técnico. | O28: Archivo Excel
A29: Precipitación histórica | B29: Hoja 2 | C29: Acumulado observado del periodo. | D29: Número | E29: mm | F29: Vacío ≠ cero; valor no negativo | G29: Sí
A30: Calidad del dato | B30: Hoja 2 | C30: Condición asignada después de revisar el registro. | D30: Categoría | E30: Lista | F30: Usar vocabulario controlado | G30: Sí
A31: Escenario SSP | B31: Hoja 3 | C31: Trayectoria socioeconómica y nivel de forzamiento. | D31: Categoría | E31: SSP | F31: Lista de cuatro escenarios | G31: Sí
A32: Horizonte | B32: Hoja 3 | C32: Periodo futuro al que corresponde la proyección. | D32: Categoría | E32: aaaa-aaaa | F32: Lista de cuatro periodos | G32: Sí
A33: Precipitación proyectada | B33: Hoja 3 | C33: Valor futuro obtenido de una fuente o modelo climático. | D33: Número | E33: mm | F33: No negativo; conservar fuente/modelo | G33: Sí
A34: Cambio absoluto | B34: Hoja 3 | C34: Diferencia entre precipitación futura y de referencia. | D34: Fórmula | E34: mm | F34: P futuro − P referencia | G34: Automático
A35: Cambio porcentual | B35: Hoja 3 | C35: Variación relativa frente al periodo histórico. | D35: Fórmula | E35: % | F35: (P futuro − P ref.) / P ref. | G35: Automático
A38: Producto asociado: ficha técnica del área, registro de fuentes, diccionario de variables y bitácora de control. Fuente curricular: CF1.docx, capítulo “Herramienta para presentación de datos históricos y proyectados”.

Sheet Hoja 2 - Histórico
A1: HOJA 2 · DATOS HISTÓRICOS DE PRECIPITACIÓN
A2: Pregunta orientadora: ¿Cómo se ha comportado la precipitación en el área de estudio durante el periodo histórico? Reemplace la serie demostrativa por registros oficiales y conserve fecha, estación, unidad, calidad, fuente y observaciones.
A4: LEYENDA | B4: Entrada | C4: Fórmula | D4: Alerta | E4: Ejemplo | F4: Unidades en encabezado
A6: TABLERO DE CALIDAD Y COMPLETITUD | N6: RESUMEN CLIMATOLÓGICO MENSUAL
A7: Indicador | B7: Resultado | C7: Indicador | D7: Resultado | E7: Indicador | F7: Resultado | G7: Indicador | H7: Resultado | I7: Indicador | J7: Resultado | K7: Indicador | L7: Resultado | N7: Mes n.º | O7: Mes | P7: Promedio (mm) | Q7: Registros
A8: Fecha inicial | B8: =MIN(A20:A379) -> 29587 | C8: Fecha final | D8: =MAX(A20:A379) -> 40513 | E8: Registros esperados | F8: 360 | G8: Registros válidos | H8: =COUNT(G20:G379) -> 360 | I8: % faltantes | J8: =COUNTBLANK(G20:G379)/F8 -> 0 | K8: Estado general | L8: =IF(AND(B9=0,D9=0,F9=0,J8=0),"APTA PARA ANÁLISIS","REVISAR ANTES DE USAR") -> APTA PARA ANÁLISIS | N8: 1 | O8: Enero | P8: =AVERAGEIF($C$20:$C$379,N8,$G$20:$G$379) -> 64.923333 | Q8: =COUNTIF($C$20:$C$379,N8) -> 30
A9: Valores negativos | B9: =COUNTIF(G20:G379,"<0") -> 0 | C9: Unidades distintas de mm | D9: =COUNTIF(H20:H379,"<>mm") -> 0 | E9: Fechas duplicadas | F9: =COUNTIF(L20:L379,"DUPLICADO") -> 0 | G9: Promedio mensual (mm) | H9: =AVERAGE(G20:G379) -> 105.81444 | I9: Mínimo mensual (mm) | J9: =MIN(G20:G379) -> 56.3 | K9: Máximo mensual (mm) | L9: =MAX(G20:G379) -> 182.3 | N9: 2 | O9: Febrero | P9: =AVERAGEIF($C$20:$C$379,N9,$G$20:$G$379) -> 75.066667 | Q9: =COUNTIF($C$20:$C$379,N9) -> 30
A10: Años completos | B10: =COUNTIF(P24:P53,12) -> 30 | C10: Horizonte requerido | D10: 30 | E10: Ceros válidos | F10: =COUNTIF(G20:G379,0) -> 0 | G10: Fuente principal | H10: ='Hoja 1 - Área y fuentes'!C20 -> Serie sintética de capacitación | I10: Periodo de referencia | J10: 1981-2010 | K10: Naturaleza | L10: Ejemplo didáctico | N10: 3 | O10: Marzo | P10: =AVERAGEIF($C$20:$C$379,N10,$G$20:$G$379) -> 110.1 | Q10: =COUNTIF($C$20:$C$379,N10) -> 30
N11: 4 | O11: Abril | P11: =AVERAGEIF($C$20:$C$379,N11,$G$20:$G$379) -> 154.97 | Q11: =COUNTIF($C$20:$C$379,N11) -> 30
A12: Regla de calidad: una celda vacía significa dato faltante; el valor 0 significa ausencia de precipitación medible. No sustituya vacíos por ceros. Antes de analizar, revise continuidad, duplicados, valores negativos, unidades y procedencia. | N12: 5 | O12: Mayo | P12: =AVERAGEIF($C$20:$C$379,N12,$G$20:$G$379) -> 139.87333 | Q12: =COUNTIF($C$20:$C$379,N12) -> 30
N13: 6 | O13: Junio | P13: =AVERAGEIF($C$20:$C$379,N13,$G$20:$G$379) -> 84.956667 | Q13: =COUNTIF($C$20:$C$379,N13) -> 30
N14: 7 | O14: Julio | P14: =AVERAGEIF($C$20:$C$379,N14,$G$20:$G$379) -> 70.03 | Q14: =COUNTIF($C$20:$C$379,N14) -> 30
N15: 8 | O15: Agosto | P15: =AVERAGEIF($C$20:$C$379,N15,$G$20:$G$379) -> 75.036667 | Q15: =COUNTIF($C$20:$C$379,N15) -> 30
N16: 9 | O16: Septiembre | P16: =AVERAGEIF($C$20:$C$379,N16,$G$20:$G$379) -> 119.96667 | Q16: =COUNTIF($C$20:$C$379,N16) -> 30
A17: MATRIZ TRAZABLE · 30 AÑOS × 12 MESES | N17: 10 | O17: Octubre | P17: =AVERAGEIF($C$20:$C$379,N17,$G$20:$G$379) -> 159.85333 | Q17: =COUNTIF($C$20:$C$379,N17) -> 30
N18: 11 | O18: Noviembre | P18: =AVERAGEIF($C$20:$C$379,N18,$G$20:$G$379) -> 134.94667 | Q18: =COUNTIF($C$20:$C$379,N18) -> 30
A19: Fecha | B19: Año | C19: Mes n.º | D19: Mes | E19: Estación / producto | F19: Código | G19: Precipitación (mm) | H19: Unidad | I19: Calidad del dato | J19: Fuente | K19: Observaciones | L19: Control | N19: 12 | O19: Diciembre | P19: =AVERAGEIF($C$20:$C$379,N19,$G$20:$G$379) -> 80.05 | Q19: =COUNTIF($C$20:$C$379,N19) -> 30
A20: 29587 | B20: 1981 | C20: 1 | D20: Enero | E20: ='Hoja 1 - Área y fuentes'!C20 -> Serie sintética de capacitación | F20: ='Hoja 1 - Área y fuentes'!D20 -> DID-001 | G20: 67.2 | H20: mm | I20: Ejemplo didáctico | J20: ='Hoja 1 - Área y fuentes'!M20 -> Sustituir por IDEAM u otra fuente oficial | K20: Sustituir por dato oficial | L20: =IF(G20="","FALTANTE",IF(G20<0,"NEGATIVO",IF(H20<>"mm","UNIDAD",IF(COUNTIF($A$20:A20,A20)>1,"DUPLICADO","OK")))) -> OK
A21: 29618 | B21: 1981 | C21: 2 | D21: Febrero | E21: ='Hoja 1 - Área y fuentes'!C20 -> Serie sintética de capacitación | F21: ='Hoja 1 - Área y fuentes'!D20 -> DID-001 | G21: 76.5 | H21: mm | I21: Ejemplo didáctico | J21: ='Hoja 1 - Área y fuentes'!M20 -> Sustituir por IDEAM u otra fuente oficial | K21: Sustituir por dato oficial | L21: =IF(G21="","FALTANTE",IF(G21<0,"NEGATIVO",IF(H21<>"mm","UNIDAD",IF(COUNTIF($A$20:A21,A21)>1,"DUPLICADO","OK")))) -> OK
A22: 29646 | B22: 1981 | C22: 3 | D22: Marzo | E22: ='Hoja 1 - Área y fuentes'!C20 -> Serie sintética de capacitación | F22: ='Hoja 1 - Área y fuentes'!D20 -> DID-001 | G22: 110.4 | H22: mm | I22: Ejemplo didáctico | J22: ='Hoja 1 - Área y fuentes'!M20 -> Sustituir por IDEAM u otra fuente oficial | K22: Sustituir por dato oficial | L22: =IF(G22="","FALTANTE",IF(G22<0,"NEGATIVO",IF(H22<>"mm","UNIDAD",IF(COUNTIF($A$20:A22,A22)>1,"DUPLICADO","OK")))) -> OK | N22: RESUMEN ANUAL
A23: 29677 | B23: 1981 | C23: 4 | D23: Abril | E23: ='Hoja 1 - Área y fuentes'!C20 -> Serie sintética de capacitación | F23: ='Hoja 1 - Área y fuentes'!D20 -> DID-001 | G23: 153.1 | H23: mm | I23: Ejemplo didáctico | J23: ='Hoja 1 - Área y fuentes'!M20 -> Sustituir por IDEAM u otra fuente oficial | K23: Sustituir por dato oficial | L23: =IF(G23="","FALTANTE",IF(G23<0,"NEGATIVO",IF(H23<>"mm","UNIDAD",IF(COUNTIF($A$20:A23,A23)>1,"DUPLICADO","OK")))) -> OK | N23: Año | O23: Precipitación anual (mm) | P23: Meses con dato | Q23: Control
A24: 29707 | B24: 1981 | C24: 5 | D24: Mayo | E24: ='Hoja 1 - Área y fuentes'!C20 -> Serie sintética de capacitación | F24: ='Hoja 1 - Área y fuentes'!D20 -> DID-001 | G24: 136.2 | H24: mm | I24: Ejemplo didáctico | J24: ='Hoja 1 - Área y fuentes'!M20 -> Sustituir por IDEAM u otra fuente oficial | K24: Sustituir por dato oficial | L24: =IF(G24="","FALTANTE",IF(G24<0,"NEGATIVO",IF(H24<>"mm","UNIDAD",IF(COUNTIF($A$20:A24,A24)>1,"DUPLICADO","OK")))) -> OK | N24: 1981 | O24: =SUMIF($B$20:$B$379,N24,$G$20:$G$379) -> 1248.6 | P24: =COUNTIF($B$20:$B$379,N24) -> 12 | Q24: =IF(P24=12,"COMPLETO","REVISAR") -> COMPLETO
A25: 29738 | B25: 1981 | C25: 6 | D25: Junio | E25: ='Hoja 1 - Área y fuentes'!C20 -> Serie sintética de capacitación | F25: ='Hoja 1 - Área y fuentes'!D20 -> DID-001 | G25: 81.7 | H25: mm | I25: Ejemplo didáctico | J25: ='Hoja 1 - Área y fuentes'!M20 -> Sustituir por IDEAM u otra fuente oficial | K25: Sustituir por dato oficial | L25: =IF(G25="","FALTANTE",IF(G25<0,"NEGATIVO",IF(H25<>"mm","UNIDAD",IF(COUNTIF($A$20:A25,A25)>1,"DUPLICADO","OK")))) -> OK | N25: 1982 | O25: =SUMIF($B$20:$B$379,N25,$G$20:$G$379) -> 1390.3 | P25: =COUNTIF($B$20:$B$379,N25) -> 12 | Q25: =IF(P25=12,"COMPLETO","REVISAR") -> COMPLETO
A26: 29768 | B26: 1981 | C26: 7 | D26: Julio | E26: ='Hoja 1 - Área y fuentes'!C20 -> Serie sintética de capacitación | F26: ='Hoja 1 - Área y fuentes'!D20 -> DID-001 | G26: 66.9 | H26: mm | I26: Ejemplo didáctico | J26: ='Hoja 1 - Área y fuentes'!M20 -> Sustituir por IDEAM u otra fuente oficial | K26: Sustituir por dato oficial | L26: =IF(G26="","FALTANTE",IF(G26<0,"NEGATIVO",IF(H26<>"mm","UNIDAD",IF(COUNTIF($A$20:A26,A26)>1,"DUPLICADO","OK")))) -> OK | N26: 1983 | O26: =SUMIF($B$20:$B$379,N26,$G$20:$G$379) -> 1349.6 | P26: =COUNTIF($B$20:$B$379,N26) -> 12 | Q26: =IF(P26=12,"COMPLETO","REVISAR") -> COMPLETO
A27: 29799 | B27: 1981 | C27: 8 | D27: Agosto | E27: ='Hoja 1 - Área y fuentes'!C20 -> Serie sintética de capacitación | F27: ='Hoja 1 - Área y fuentes'!D20 -> DID-001 | G27: 71.7 | H27: mm | I27: Ejemplo didáctico | J27: ='Hoja 1 - Área y fuentes'!M20 -> Sustituir por IDEAM u otra fuente oficial | K27: Sustituir por dato oficial | L27: =IF(G27="","FALTANTE",IF(G27<0,"NEGATIVO",IF(H27<>"mm","UNIDAD",IF(COUNTIF($A$20:A27,A27)>1,"DUPLICADO","OK")))) -> OK | N27: 1984 | O27: =SUMIF($B$20:$B$379,N27,$G$20:$G$379) -> 1168.8 | P27: =COUNTIF($B$20:$B$379,N27) -> 12 | Q27: =IF(P27=12,"COMPLETO","REVISAR") -> COMPLETO
A28: 29830 | B28: 1981 | C28: 9 | D28: Septiembre | E28: ='Hoja 1 - Área y fuentes'!C20 -> Serie sintética de capacitación | F28: ='Hoja 1 - Área y fuentes'!D20 -> DID-001 | G28: 115.4 | H28: mm | I28: Ejemplo didáctico | J28: ='Hoja 1 - Área y fuentes'!M20 -> Sustituir por IDEAM u otra fuente oficial | K28: Sustituir por dato oficial | L28: =IF(G28="","FALTANTE",IF(G28<0,"NEGATIVO",IF(H28<>"mm","UNIDAD",IF(COUNTIF($A$20:A28,A28)>1,"DUPLICADO","OK")))) -> OK | N28: 1985 | O28: =SUMIF($B$20:$B$379,N28,$G$20:$G$379) -> 1146.3 | P28: =COUNTIF($B$20:$B$379,N28) -> 12 | Q28: =IF(P28=12,"COMPLETO","REVISAR") -> COMPLETO
A29: 29860 | B29: 1981 | C29: 10 | D29: Octubre | E29: ='Hoja 1 - Área y fuentes'!C20 -> Serie sintética de capacitación | F29: ='Hoja 1 - Área y fuentes'!D20 -> DID-001 | G29: 155.7 | H29: mm | I29: Ejemplo didáctico | J29: ='Hoja 1 - Área y fuentes'!M20 -> Sustituir por IDEAM u otra fuente oficial | K29: Sustituir por dato oficial | L29: =IF(G29="","FALTANTE",IF(G29<0,"NEGATIVO",IF(H29<>"mm","UNIDAD",IF(COUNTIF($A$20:A29,A29)>1,"DUPLICADO","OK")))) -> OK | N29: 1986 | O29: =SUMIF($B$20:$B$379,N29,$G$20:$G$379) -> 1307 | P29: =COUNTIF($B$20:$B$379,N29) -> 12 | Q29: =IF(P29=12,"COMPLETO","REVISAR") -> COMPLETO
A30: 29891 | B30: 1981 | C30: 11 | D30: Noviembre | E30: ='Hoja 1 - Área y fuentes'!C20 -> Serie sintética de capacitación | F30: ='Hoja 1 - Área y fuentes'!D20 -> DID-001 | G30: 133.4 | H30: mm | I30: Ejemplo didáctico | J30: ='Hoja 1 - Área y fuentes'!M20 -> Sustituir por IDEAM u otra fuente oficial | K30: Sustituir por dato oficial | L30: =IF(G30="","FALTANTE",IF(G30<0,"NEGATIVO",IF(H30<>"mm","UNIDAD",IF(COUNTIF($A$20:A30,A30)>1,"DUPLICADO","OK")))) -> OK | N30: 1987 | O30: =SUMIF($B$20:$B$379,N30,$G$20:$G$379) -> 1410.1 | P30: =COUNTIF($B$20:$B$379,N30) -> 12 | Q30: =IF(P30=12,"COMPLETO","REVISAR") -> COMPLETO
A31: 29921 | B31: 1981 | C31: 12 | D31: Diciembre | E31: ='Hoja 1 - Área y fuentes'!C20 -> Serie sintética de capacitación | F31: ='Hoja 1 - Área y fuentes'!D20 -> DID-001 | G31: 80.4 | H31: mm | I31: Ejemplo didáctico | J31: ='Hoja 1 - Área y fuentes'!M20 -> Sustituir por IDEAM u otra fuente oficial | K31: Sustituir por dato oficial | L31: =IF(G31="","FALTANTE",IF(G31<0,"NEGATIVO",IF(H31<>"mm","UNIDAD",IF(COUNTIF($A$20:A31,A31)>1,"DUPLICADO","OK")))) -> OK | N31: 1988 | O31: =SUMIF($B$20:$B$379,N31,$G$20:$G$379) -> 1307.6 | P31: =COUNTIF($B$20:$B$379,N31) -> 12 | Q31: =IF(P31=12,"COMPLETO","REVISAR") -> COMPLETO
A32: 29952 | B32: 1982 | C32: 1 | D32: Enero | E32: ='Hoja 1 - Área y fuentes'!C20 -> Serie sintética de capacitación | F32: ='Hoja 1 - Área y fuentes'!D20 -> DID-001 | G32: 72.2 | H32: mm | I32: Ejemplo didáctico | J32: ='Hoja 1 - Área y fuentes'!M20 -> Sustituir por IDEAM u otra fuente oficial | K32: Sustituir por dato oficial | L32: =IF(G32="","FALTANTE",IF(G32<0,"NEGATIVO",IF(H32<>"mm","UNIDAD",IF(COUNTIF($A$20:A32,A32)>1,"DUPLICADO","OK")))) -> OK | N32: 1989 | O32: =SUMIF($B$20:$B$379,N32,$G$20:$G$379) -> 1151 | P32: =COUNTIF($B$20:$B$379,N32) -> 12 | Q32: =IF(P32=12,"COMPLETO","REVISAR") -> COMPLETO
A33: 29983 | B33: 1982 | C33: 2 | D33: Febrero | E33: ='Hoja 1 - Área y fuentes'!C20 -> Serie sintética de capacitación | F33: ='Hoja 1 - Área y fuentes'!D20 -> DID-001 | G33: 80.9 | H33: mm | I33: Ejemplo didáctico | J33: ='Hoja 1 - Área y fuentes'!M20 -> Sustituir por IDEAM u otra fuente oficial | K33: Sustituir por dato oficial | L33: =IF(G33="","FALTANTE",IF(G33<0,"NEGATIVO",IF(H33<>"mm","UNIDAD",IF(COUNTIF($A$20:A33,A33)>1,"DUPLICADO","OK")))) -> OK | N33: 1990 | O33: =SUMIF($B$20:$B$379,N33,$G$20:$G$379) -> 1172.5 | P33: =COUNTIF($B$20:$B$379,N33) -> 12 | Q33: =IF(P33=12,"COMPLETO","REVISAR") -> COMPLETO
A34: 30011 | B34: 1982 | C34: 3 | D34: Marzo | E34: ='Hoja 1 - Área y fuentes'!C20 -> Serie sintética de capacitación | F34: ='Hoja 1 - Área y fuentes'!D20 -> DID-001 | G34: 116.8 | H34: mm | I34: Ejemplo didáctico | J34: ='Hoja 1 - Área y fuentes'!M20 -> Sustituir por IDEAM u otra fuente oficial | K34: Sustituir por dato oficial | L34: =IF(G34="","FALTANTE",IF(G34<0,"NEGATIVO",IF(H34<>"mm","UNIDAD",IF(COUNTIF($A$20:A34,A34)>1,"DUPLICADO","OK")))) -> OK | N34: 1991 | O34: =SUMIF($B$20:$B$379,N34,$G$20:$G$379) -> 1341.1 | P34: =COUNTIF($B$20:$B$379,N34) -> 12 | Q34: =IF(P34=12,"COMPLETO","REVISAR") -> COMPLETO
A35: 30042 | B35: 1982 | C35: 4 | D35: Abril | E35: ='Hoja 1 - Área y fuentes'!C20 -> Serie sintética de capacitación | F35: ='Hoja 1 - Área y fuentes'!D20 -> DID-001 | G35: 165.6 | H35: mm | I35: Ejemplo didáctico | J35: ='Hoja 1 - Área y fuentes'!M20 -> Sustituir por IDEAM u otra fuente oficial | K35: Sustituir por dato oficial | L35: =IF(G35="","FALTANTE",IF(G35<0,"NEGATIVO",IF(H35<>"mm","UNIDAD",IF(COUNTIF($A$20:A35,A35)>1,"DUPLICADO","OK")))) -> OK | N35: 1992 | O35: =SUMIF($B$20:$B$379,N35,$G$20:$G$379) -> 1401.3 | P35: =COUNTIF($B$20:$B$379,N35) -> 12 | Q35: =IF(P35=12,"COMPLETO","REVISAR") -> COMPLETO
A36: 30072 | B36: 1982 | C36: 5 | D36: Mayo | E36: ='Hoja 1 - Área y fuentes'!C20 -> Serie sintética de capacitación | F36: ='Hoja 1 - Área y fuentes'!D20 -> DID-001 | G36: 153.2 | H36: mm | I36: Ejemplo didáctico | J36: ='Hoja 1 - Área y fuentes'!M20 -> Sustituir por IDEAM u otra fuente oficial | K36: Sustituir por dato oficial | L36: =IF(G36="","FALTANTE",IF(G36<0,"NEGATIVO",IF(H36<>"mm","UNIDAD",IF(COUNTIF($A$20:A36,A36)>1,"DUPLICADO","OK")))) -> OK | N36: 1993 | O36: =SUMIF($B$20:$B$379,N36,$G$20:$G$379) -> 1265.9 | P36: =COUNTIF($B$20:$B$379,N36) -> 12 | Q36: =IF(P36=12,"COMPLETO","REVISAR") -> COMPLETO
A37: 30103 | B37: 1982 | C37: 6 | D37: Junio | E37: ='Hoja 1 - Área y fuentes'!C20 -> Serie sintética de capacitación | F37: ='Hoja 1 - Área y fuentes'!D20 -> DID-001 | G37: 95.8 | H37: mm | I37: Ejemplo didáctico | J37: ='Hoja 1 - Área y fuentes'!M20 -> Sustituir por IDEAM u otra fuente oficial | K37: Sustituir por dato oficial | L37: =IF(G37="","FALTANTE",IF(G37<0,"NEGATIVO",IF(H37<>"mm","UNIDAD",IF(COUNTIF($A$20:A37,A37)>1,"DUPLICADO","OK")))) -> OK | N37: 1994 | O37: =SUMIF($B$20:$B$379,N37,$G$20:$G$379) -> 1144.6 | P37: =COUNTIF($B$20:$B$379,N37) -> 12 | Q37: =IF(P37=12,"COMPLETO","REVISAR") -> COMPLETO
A38: 30133 | B38: 1982 | C38: 7 | D38: Julio | E38: ='Hoja 1 - Área y fuentes'!C20 -> Serie sintética de capacitación | F38: ='Hoja 1 - Área y fuentes'!D20 -> DID-001 | G38: 80.4 | H38: mm | I38: Ejemplo didáctico | J38: ='Hoja 1 - Área y fuentes'!M20 -> Sustituir por IDEAM u otra fuente oficial | K38: Sustituir por dato oficial | L38: =IF(G38="","FALTANTE",IF(G38<0,"NEGATIVO",IF(H38<>"mm","UNIDAD",IF(COUNTIF($A$20:A38,A38)>1,"DUPLICADO","OK")))) -> OK | N38: 1995 | O38: =SUMIF($B$20:$B$379,N38,$G$20:$G$379) -> 1187.6 | P38: =COUNTIF($B$20:$B$379,N38) -> 12 | Q38: =IF(P38=12,"COMPLETO","REVISAR") -> COMPLETO
A39: 30164 | B39: 1982 | C39: 8 | D39: Agosto | E39: ='Hoja 1 - Área y fuentes'!C20 -> Serie sintética de capacitación | F39: ='Hoja 1 - Área y fuentes'!D20 -> DID-001 | G39: 86.1 | H39: mm | I39: Ejemplo didáctico | J39: ='Hoja 1 - Área y fuentes'!M20 -> Sustituir por IDEAM u otra fuente oficial | K39: Sustituir por dato oficial | L39: =IF(G39="","FALTANTE",IF(G39<0,"NEGATIVO",IF(H39<>"mm","UNIDAD",IF(COUNTIF($A$20:A39,A39)>1,"DUPLICADO","OK")))) -> OK | N39: 1996 | O39: =SUMIF($B$20:$B$379,N39,$G$20:$G$379) -> 1348.3 | P39: =COUNTIF($B$20:$B$379,N39) -> 12 | Q39: =IF(P39=12,"COMPLETO","REVISAR") -> COMPLETO
A40: 30195 | B40: 1982 | C40: 9 | D40: Septiembre | E40: ='Hoja 1 - Área y fuentes'!C20 -> Serie sintética de capacitación | F40: ='Hoja 1 - Área y fuentes'!D20 -> DID-001 | G40: 135.1 | H40: mm | I40: Ejemplo didáctico | J40: ='Hoja 1 - Área y fuentes'!M20 -> Sustituir por IDEAM u otra fuente oficial | K40: Sustituir por dato oficial | L40: =IF(G40="","FALTANTE",IF(G40<0,"NEGATIVO",IF(H40<>"mm","UNIDAD",IF(COUNTIF($A$20:A40,A40)>1,"DUPLICADO","OK")))) -> OK | N40: 1997 | O40: =SUMIF($B$20:$B$379,N40,$G$20:$G$379) -> 1446.9 | P40: =COUNTIF($B$20:$B$379,N40) -> 12 | Q40: =IF(P40=12,"COMPLETO","REVISAR") -> COMPLETO
A41: 30225 | B41: 1982 | C41: 10 | D41: Octubre | E41: ='Hoja 1 - Área y fuentes'!C20 -> Serie sintética de capacitación | F41: ='Hoja 1 - Área y fuentes'!D20 -> DID-001 | G41: 175 | H41: mm | I41: Ejemplo didáctico | J41: ='Hoja 1 - Área y fuentes'!M20 -> Sustituir por IDEAM u otra fuente oficial | K41: Sustituir por dato oficial | L41: =IF(G41="","FALTANTE",IF(G41<0,"NEGATIVO",IF(H41<>"mm","UNIDAD",IF(COUNTIF($A$20:A41,A41)>1,"DUPLICADO","OK")))) -> OK | N41: 1998 | O41: =SUMIF($B$20:$B$379,N41,$G$20:$G$379) -> 1211.1 | P41: =COUNTIF($B$20:$B$379,N41) -> 12 | Q41: =IF(P41=12,"COMPLETO","REVISAR") -> COMPLETO
A42: 30256 | B42: 1982 | C42: 11 | D42: Noviembre | E42: ='Hoja 1 - Área y fuentes'!C20 -> Serie sintética de capacitación | F42: ='Hoja 1 - Área y fuentes'!D20 -> DID-001 | G42: 144.2 | H42: mm | I42: Ejemplo didáctico | J42: ='Hoja 1 - Área y fuentes'!M20 -> Sustituir por IDEAM u otra fuente oficial | K42: Sustituir por dato oficial | L42: =IF(G42="","FALTANTE",IF(G42<0,"NEGATIVO",IF(H42<>"mm","UNIDAD",IF(COUNTIF($A$20:A42,A42)>1,"DUPLICADO","OK")))) -> OK | N42: 1999 | O42: =SUMIF($B$20:$B$379,N42,$G$20:$G$379) -> 1114.9 | P42: =COUNTIF($B$20:$B$379,N42) -> 12 | Q42: =IF(P42=12,"COMPLETO","REVISAR") -> COMPLETO | S42: Interpretación: examine estacionalidad, variación entre años, extremos y vacíos antes de trasladar la serie a la Hoja 4. Las gráficas son salidas de apoyo y no reemplazan la revisión de calidad.
...

Sheet Hoja 3 - Proyecciones
A1: HOJA 3 · DATOS PROYECTADOS DE PRECIPITACIÓN
A2: Pregunta orientadora: ¿Cómo podría cambiar la precipitación bajo diferentes escenarios y horizontes? Registre proyecciones comparables con la referencia histórica y documente escenario, periodo, modelo, resolución, fuente e incertidumbre.
A4: LEYENDA | B4: Entrada | C4: Fórmula | D4: Alerta | E4: Ejemplo | F4: Unidades en encabezado
A6: TABLERO DE VALIDACIÓN DE PROYECCIONES | P6: RESUMEN POR ESCENARIO Y HORIZONTE
A7: Indicador | B7: Resultado | C7: Indicador | D7: Resultado | E7: Indicador | F7: Resultado | G7: Indicador | H7: Resultado | I7: Indicador | J7: Resultado | K7: Indicador | L7: Resultado | M7: Indicador | N7: Resultado | P7: Escenario | Q7: Horizonte | R7: Histórico anual (mm) | S7: Proyectado anual (mm) | T7: Cambio (%) | V7: Horizonte | W7: SSP1-2.6 | X7: SSP2-4.5 | Y7: SSP3-7.0 | Z7: SSP5-8.5
A8: Registros esperados | B8: 192 | C8: Registros cargados | D8: =COUNT(G20:G211) -> 192 | E8: Registros con alerta | F8: =COUNTIF(N20:N211,"<>OK") -> 0 | G8: Cambio mínimo | H8: =MIN(I20:I211) -> -0.18057196 | I8: Cambio máximo | J8: =MAX(I20:I211) -> 0.020612117 | K8: Referencia histórica | L8: =SUM('Hoja 2 - Histórico'!P8:P19) -> 1269.7733 | M8: Escenarios / horizontes | N8: 4 / 4 | P8: SSP1-2.6 | Q8: 2021-2040 | R8: =SUM('Hoja 2 - Histórico'!P8:P19) -> 1269.7733 | S8: =SUMIFS($G$20:$G$211,$A$20:$A$211,P8,$B$20:$B$211,Q8) -> 1295.3 | T8: =IF(R8=0,"",(S8-R8)/R8) -> 0.020103326 | V8: 2021-2040 | W8: =SUMIFS($G$20:$G$211,$A$20:$A$211,W$7,$B$20:$B$211,$V8) -> 1295.3 | X8: =SUMIFS($G$20:$G$211,$A$20:$A$211,X$7,$B$20:$B$211,$V8) -> 1282.6 | Y8: =SUMIFS($G$20:$G$211,$A$20:$A$211,Y$7,$B$20:$B$211,$V8) -> 1257.1 | Z8: =SUMIFS($G$20:$G$211,$A$20:$A$211,Z$7,$B$20:$B$211,$V8) -> 1244.4
A9: Naturaleza | B9: Proyección, no predicción | C9: Unidad requerida | D9: mm | E9: Periodo histórico | F9: 1981-2010 | G9: Modelos | H9: Conservar identificación | I9: Resolución | J9: Mensual | K9: Fuente | L9: Conservar URL/producto | M9: Fecha de consulta | N9: Registrar | P9: SSP1-2.6 | Q9: 2041-2060 | R9: =SUM('Hoja 2 - Histórico'!P8:P19) -> 1269.7733 | S9: =SUMIFS($G$20:$G$211,$A$20:$A$211,P9,$B$20:$B$211,Q9) -> 1282.6 | T9: =IF(R9=0,"",(S9-R9)/R9) -> 0.01010154 | V9: 2041-2060 | W9: =SUMIFS($G$20:$G$211,$A$20:$A$211,W$7,$B$20:$B$211,$V9) -> 1282.6 | X9: =SUMIFS($G$20:$G$211,$A$20:$A$211,X$7,$B$20:$B$211,$V9) -> 1244.4 | Y9: =SUMIFS($G$20:$G$211,$A$20:$A$211,Y$7,$B$20:$B$211,$V9) -> 1219 | Z9: =SUMIFS($G$20:$G$211,$A$20:$A$211,Z$7,$B$20:$B$211,$V9) -> 1193.6
A10: Control pedagógico | B10: Compare periodos equivalentes | C10: Control técnico | D10: No mezclar escalas/unidades | E10: Incertidumbre | F10: Declarar dispersión/modelos | G10: Salida | H10: Cambio absoluto y porcentual | I10: Producto | J10: Base trazable | K10: Uso posterior | L10: Hoja 4 | M10: Estado general | N10: =IF(F8=0,"APTA PARA ANÁLISIS","REVISAR") -> APTA PARA ANÁLISIS | P10: SSP1-2.6 | Q10: 2061-2080 | R10: =SUM('Hoja 2 - Histórico'!P8:P19) -> 1269.7733 | S10: =SUMIFS($G$20:$G$211,$A$20:$A$211,P10,$B$20:$B$211,Q10) -> 1257.1 | T10: =IF(R10=0,"",(S10-R10)/R10) -> -0.009980784 | V10: 2061-2080 | W10: =SUMIFS($G$20:$G$211,$A$20:$A$211,W$7,$B$20:$B$211,$V10) -> 1257.1 | X10: =SUMIFS($G$20:$G$211,$A$20:$A$211,X$7,$B$20:$B$211,$V10) -> 1219 | Y10: =SUMIFS($G$20:$G$211,$A$20:$A$211,Y$7,$B$20:$B$211,$V10) -> 1168.3 | Z10: =SUMIFS($G$20:$G$211,$A$20:$A$211,Z$7,$B$20:$B$211,$V10) -> 1117.5
P11: SSP1-2.6 | Q11: 2081-2100 | R11: =SUM('Hoja 2 - Histórico'!P8:P19) -> 1269.7733 | S11: =SUMIFS($G$20:$G$211,$A$20:$A$211,P11,$B$20:$B$211,Q11) -> 1244.4 | T11: =IF(R11=0,"",(S11-R11)/R11) -> -0.019982569 | V11: 2081-2100 | W11: =SUMIFS($G$20:$G$211,$A$20:$A$211,W$7,$B$20:$B$211,$V11) -> 1244.4 | X11: =SUMIFS($G$20:$G$211,$A$20:$A$211,X$7,$B$20:$B$211,$V11) -> 1193.6 | Y11: =SUMIFS($G$20:$G$211,$A$20:$A$211,Y$7,$B$20:$B$211,$V11) -> 1117.5 | Z11: =SUMIFS($G$20:$G$211,$A$20:$A$211,Z$7,$B$20:$B$211,$V11) -> 1041.3
A12: Los valores precargados son un conjunto demostrativo construido a partir de la climatología de la Hoja 2. Sustitúyalos por proyecciones oficiales o resultados de modelos y conserve el periodo de referencia, escenario, horizonte, modelo, resolución y fuente. | P12: SSP2-4.5 | Q12: 2021-2040 | R12: =SUM('Hoja 2 - Histórico'!P8:P19) -> 1269.7733 | S12: =SUMIFS($G$20:$G$211,$A$20:$A$211,P12,$B$20:$B$211,Q12) -> 1282.6 | T12: =IF(R12=0,"",(S12-R12)/R12) -> 0.01010154
P13: SSP2-4.5 | Q13: 2041-2060 | R13: =SUM('Hoja 2 - Histórico'!P8:P19) -> 1269.7733 | S13: =SUMIFS($G$20:$G$211,$A$20:$A$211,P13,$B$20:$B$211,Q13) -> 1244.4 | T13: =IF(R13=0,"",(S13-R13)/R13) -> -0.019982569
P14: SSP2-4.5 | Q14: 2061-2080 | R14: =SUM('Hoja 2 - Histórico'!P8:P19) -> 1269.7733 | S14: =SUMIFS($G$20:$G$211,$A$20:$A$211,P14,$B$20:$B$211,Q14) -> 1219 | T14: =IF(R14=0,"",(S14-R14)/R14) -> -0.039986139
P15: SSP2-4.5 | Q15: 2081-2100 | R15: =SUM('Hoja 2 - Histórico'!P8:P19) -> 1269.7733 | S15: =SUMIFS($G$20:$G$211,$A$20:$A$211,P15,$B$20:$B$211,Q15) -> 1193.6 | T15: =IF(R15=0,"",(S15-R15)/R15) -> -0.059989709
P16: SSP3-7.0 | Q16: 2021-2040 | R16: =SUM('Hoja 2 - Histórico'!P8:P19) -> 1269.7733 | S16: =SUMIFS($G$20:$G$211,$A$20:$A$211,P16,$B$20:$B$211,Q16) -> 1257.1 | T16: =IF(R16=0,"",(S16-R16)/R16) -> -0.009980784
A17: BASE TRAZABLE DE PROYECCIONES · 4 ESCENARIOS × 4 HORIZONTES × 12 MESES | P17: SSP3-7.0 | Q17: 2041-2060 | R17: =SUM('Hoja 2 - Histórico'!P8:P19) -> 1269.7733 | S17: =SUMIFS($G$20:$G$211,$A$20:$A$211,P17,$B$20:$B$211,Q17) -> 1219 | T17: =IF(R17=0,"",(S17-R17)/R17) -> -0.039986139
P18: SSP3-7.0 | Q18: 2061-2080 | R18: =SUM('Hoja 2 - Histórico'!P8:P19) -> 1269.7733 | S18: =SUMIFS($G$20:$G$211,$A$20:$A$211,P18,$B$20:$B$211,Q18) -> 1168.3 | T18: =IF(R18=0,"",(S18-R18)/R18) -> -0.079914525
A19: Escenario SSP | B19: Horizonte | C19: Año representativo | D19: Mes n.º | E19: Mes | F19: P histórica ref. (mm) | G19: P proyectada (mm) | H19: Cambio absoluto (mm) | I19: Cambio (%) | J19: Unidad | K19: Modelo / conjunto | L19: Fuente / producto | M19: Observaciones e incertidumbre | N19: Control | P19: SSP3-7.0 | Q19: 2081-2100 | R19: =SUM('Hoja 2 - Histórico'!P8:P19) -> 1269.7733 | S19: =SUMIFS($G$20:$G$211,$A$20:$A$211,P19,$B$20:$B$211,Q19) -> 1117.5 | T19: =IF(R19=0,"",(S19-R19)/R19) -> -0.11992167
A20: SSP1-2.6 | B20: 2021-2040 | C20: 2030 | D20: 1 | E20: Enero | F20: =INDEX('Hoja 2 - Histórico'!$P$8:$P$19,MATCH(D20,'Hoja 2 - Histórico'!$N$8:$N$19,0)) -> 64.923333 | G20: 66.2 | H20: =G20-F20 -> 1.2766667 | I20: =IF(F20=0,"",(G20-F20)/F20) -> 0.019664219 | J20: mm | K20: Conjunto demostrativo | L20: Sustituir por IDEAM/CMIP6 | M20: Ejemplo; declarar dispersión y limitaciones | N20: =IF(OR(G20<0,J20<>"mm",K20="",L20=""),"REVISAR","OK") -> OK | P20: SSP5-8.5 | Q20: 2021-2040 | R20: =SUM('Hoja 2 - Histórico'!P8:P19) -> 1269.7733 | S20: =SUMIFS($G$20:$G$211,$A$20:$A$211,P20,$B$20:$B$211,Q20) -> 1244.4 | T20: =IF(R20=0,"",(S20-R20)/R20) -> -0.019982569
A21: SSP1-2.6 | B21: 2021-2040 | C21: 2030 | D21: 2 | E21: Febrero | F21: =INDEX('Hoja 2 - Histórico'!$P$8:$P$19,MATCH(D21,'Hoja 2 - Histórico'!$N$8:$N$19,0)) -> 75.066667 | G21: 76.6 | H21: =G21-F21 -> 1.5333333 | I21: =IF(F21=0,"",(G21-F21)/F21) -> 0.020426288 | J21: mm | K21: Conjunto demostrativo | L21: Sustituir por IDEAM/CMIP6 | M21: Ejemplo; declarar dispersión y limitaciones | N21: =IF(OR(G21<0,J21<>"mm",K21="",L21=""),"REVISAR","OK") -> OK | P21: SSP5-8.5 | Q21: 2041-2060 | R21: =SUM('Hoja 2 - Histórico'!P8:P19) -> 1269.7733 | S21: =SUMIFS($G$20:$G$211,$A$20:$A$211,P21,$B$20:$B$211,Q21) -> 1193.6 | T21: =IF(R21=0,"",(S21-R21)/R21) -> -0.059989709
A22: SSP1-2.6 | B22: 2021-2040 | C22: 2030 | D22: 3 | E22: Marzo | F22: =INDEX('Hoja 2 - Histórico'!$P$8:$P$19,MATCH(D22,'Hoja 2 - Histórico'!$N$8:$N$19,0)) -> 110.1 | G22: 112.3 | H22: =G22-F22 -> 2.2 | I22: =IF(F22=0,"",(G22-F22)/F22) -> 0.019981835 | J22: mm | K22: Conjunto demostrativo | L22: Sustituir por IDEAM/CMIP6 | M22: Ejemplo; declarar dispersión y limitaciones | N22: =IF(OR(G22<0,J22<>"mm",K22="",L22=""),"REVISAR","OK") -> OK | P22: SSP5-8.5 | Q22: 2061-2080 | R22: =SUM('Hoja 2 - Histórico'!P8:P19) -> 1269.7733 | S22: =SUMIFS($G$20:$G$211,$A$20:$A$211,P22,$B$20:$B$211,Q22) -> 1117.5 | T22: =IF(R22=0,"",(S22-R22)/R22) -> -0.11992167
A23: SSP1-2.6 | B23: 2021-2040 | C23: 2030 | D23: 4 | E23: Abril | F23: =INDEX('Hoja 2 - Histórico'!$P$8:$P$19,MATCH(D23,'Hoja 2 - Histórico'!$N$8:$N$19,0)) -> 154.97 | G23: 158.1 | H23: =G23-F23 -> 3.13 | I23: =IF(F23=0,"",(G23-F23)/F23) -> 0.020197458 | J23: mm | K23: Conjunto demostrativo | L23: Sustituir por IDEAM/CMIP6 | M23: Ejemplo; declarar dispersión y limitaciones | N23: =IF(OR(G23<0,J23<>"mm",K23="",L23=""),"REVISAR","OK") -> OK | P23: SSP5-8.5 | Q23: 2081-2100 | R23: =SUM('Hoja 2 - Histórico'!P8:P19) -> 1269.7733 | S23: =SUMIFS($G$20:$G$211,$A$20:$A$211,P23,$B$20:$B$211,Q23) -> 1041.3 | T23: =IF(R23=0,"",(S23-R23)/R23) -> -0.17993238
A24: SSP1-2.6 | B24: 2021-2040 | C24: 2030 | D24: 5 | E24: Mayo | F24: =INDEX('Hoja 2 - Histórico'!$P$8:$P$19,MATCH(D24,'Hoja 2 - Histórico'!$N$8:$N$19,0)) -> 139.87333 | G24: 142.7 | H24: =G24-F24 -> 2.8266667 | I24: =IF(F24=0,"",(G24-F24)/F24) -> 0.02020876 | J24: mm | K24: Conjunto demostrativo | L24: Sustituir por IDEAM/CMIP6 | M24: Ejemplo; declarar dispersión y limitaciones | N24: =IF(OR(G24<0,J24<>"mm",K24="",L24=""),"REVISAR","OK") -> OK
A25: SSP1-2.6 | B25: 2021-2040 | C25: 2030 | D25: 6 | E25: Junio | F25: =INDEX('Hoja 2 - Histórico'!$P$8:$P$19,MATCH(D25,'Hoja 2 - Histórico'!$N$8:$N$19,0)) -> 84.956667 | G25: 86.7 | H25: =G25-F25 -> 1.7433333 | I25: =IF(F25=0,"",(G25-F25)/F25) -> 0.020520265 | J25: mm | K25: Conjunto demostrativo | L25: Sustituir por IDEAM/CMIP6 | M25: Ejemplo; declarar dispersión y limitaciones | N25: =IF(OR(G25<0,J25<>"mm",K25="",L25=""),"REVISAR","OK") -> OK
A26: SSP1-2.6 | B26: 2021-2040 | C26: 2030 | D26: 7 | E26: Julio | F26: =INDEX('Hoja 2 - Histórico'!$P$8:$P$19,MATCH(D26,'Hoja 2 - Histórico'!$N$8:$N$19,0)) -> 70.03 | G26: 71.4 | H26: =G26-F26 -> 1.37 | I26: =IF(F26=0,"",(G26-F26)/F26) -> 0.019563044 | J26: mm | K26: Conjunto demostrativo | L26: Sustituir por IDEAM/CMIP6 | M26: Ejemplo; declarar dispersión y limitaciones | N26: =IF(OR(G26<0,J26<>"mm",K26="",L26=""),"REVISAR","OK") -> OK
A27: SSP1-2.6 | B27: 2021-2040 | C27: 2030 | D27: 8 | E27: Agosto | F27: =INDEX('Hoja 2 - Histórico'!$P$8:$P$19,MATCH(D27,'Hoja 2 - Histórico'!$N$8:$N$19,0)) -> 75.036667 | G27: 76.5 | H27: =G27-F27 -> 1.4633333 | I27: =IF(F27=0,"",(G27-F27)/F27) -> 0.019501577 | J27: mm | K27: Conjunto demostrativo | L27: Sustituir por IDEAM/CMIP6 | M27: Ejemplo; declarar dispersión y limitaciones | N27: =IF(OR(G27<0,J27<>"mm",K27="",L27=""),"REVISAR","OK") -> OK
A28: SSP1-2.6 | B28: 2021-2040 | C28: 2030 | D28: 9 | E28: Septiembre | F28: =INDEX('Hoja 2 - Histórico'!$P$8:$P$19,MATCH(D28,'Hoja 2 - Histórico'!$N$8:$N$19,0)) -> 119.96667 | G28: 122.4 | H28: =G28-F28 -> 2.4333333 | I28: =IF(F28=0,"",(G28-F28)/F28) -> 0.020283412 | J28: mm | K28: Conjunto demostrativo | L28: Sustituir por IDEAM/CMIP6 | M28: Ejemplo; declarar dispersión y limitaciones | N28: =IF(OR(G28<0,J28<>"mm",K28="",L28=""),"REVISAR","OK") -> OK
A29: SSP1-2.6 | B29: 2021-2040 | C29: 2030 | D29: 10 | E29: Octubre | F29: =INDEX('Hoja 2 - Histórico'!$P$8:$P$19,MATCH(D29,'Hoja 2 - Histórico'!$N$8:$N$19,0)) -> 159.85333 | G29: 163.1 | H29: =G29-F29 -> 3.2466667 | I29: =IF(F29=0,"",(G29-F29)/F29) -> 0.020310284 | J29: mm | K29: Conjunto demostrativo | L29: Sustituir por IDEAM/CMIP6 | M29: Ejemplo; declarar dispersión y limitaciones | N29: =IF(OR(G29<0,J29<>"mm",K29="",L29=""),"REVISAR","OK") -> OK
A30: SSP1-2.6 | B30: 2021-2040 | C30: 2030 | D30: 11 | E30: Noviembre | F30: =INDEX('Hoja 2 - Histórico'!$P$8:$P$19,MATCH(D30,'Hoja 2 - Histórico'!$N$8:$N$19,0)) -> 134.94667 | G30: 137.6 | H30: =G30-F30 -> 2.6533333 | I30: =IF(F30=0,"",(G30-F30)/F30) -> 0.019662089 | J30: mm | K30: Conjunto demostrativo | L30: Sustituir por IDEAM/CMIP6 | M30: Ejemplo; declarar dispersión y limitaciones | N30: =IF(OR(G30<0,J30<>"mm",K30="",L30=""),"REVISAR","OK") -> OK
A31: SSP1-2.6 | B31: 2021-2040 | C31: 2030 | D31: 12 | E31: Diciembre | F31: =INDEX('Hoja 2 - Histórico'!$P$8:$P$19,MATCH(D31,'Hoja 2 - Histórico'!$N$8:$N$19,0)) -> 80.05 | G31: 81.7 | H31: =G31-F31 -> 1.65 | I31: =IF(F31=0,"",(G31-F31)/F31) -> 0.020612117 | J31: mm | K31: Conjunto demostrativo | L31: Sustituir por IDEAM/CMIP6 | M31: Ejemplo; declarar dispersión y limitaciones | N31: =IF(OR(G31<0,J31<>"mm",K31="",L31=""),"REVISAR","OK") -> OK
A32: SSP1-2.6 | B32: 2041-2060 | C32: 2050 | D32: 1 | E32: Enero | F32: =INDEX('Hoja 2 - Histórico'!$P$8:$P$19,MATCH(D32,'Hoja 2 - Histórico'!$N$8:$N$19,0)) -> 64.923333 | G32: 65.6 | H32: =G32-F32 -> 0.67666667 | I32: =IF(F32=0,"",(G32-F32)/F32) -> 0.01042255 | J32: mm | K32: Conjunto demostrativo | L32: Sustituir por IDEAM/CMIP6 | M32: Ejemplo; declarar dispersión y limitaciones | N32: =IF(OR(G32<0,J32<>"mm",K32="",L32=""),"REVISAR","OK") -> OK
A33: SSP1-2.6 | B33: 2041-2060 | C33: 2050 | D33: 2 | E33: Febrero | F33: =INDEX('Hoja 2 - Histórico'!$P$8:$P$19,MATCH(D33,'Hoja 2 - Histórico'!$N$8:$N$19,0)) -> 75.066667 | G33: 75.8 | H33: =G33-F33 -> 0.73333333 | I33: =IF(F33=0,"",(G33-F33)/F33) -> 0.0097690941 | J33: mm | K33: Conjunto demostrativo | L33: Sustituir por IDEAM/CMIP6 | M33: Ejemplo; declarar dispersión y limitaciones | N33: =IF(OR(G33<0,J33<>"mm",K33="",L33=""),"REVISAR","OK") -> OK
A34: SSP1-2.6 | B34: 2041-2060 | C34: 2050 | D34: 3 | E34: Marzo | F34: =INDEX('Hoja 2 - Histórico'!$P$8:$P$19,MATCH(D34,'Hoja 2 - Histórico'!$N$8:$N$19,0)) -> 110.1 | G34: 111.2 | H34: =G34-F34 -> 1.1 | I34: =IF(F34=0,"",(G34-F34)/F34) -> 0.0099909173 | J34: mm | K34: Conjunto demostrativo | L34: Sustituir por IDEAM/CMIP6 | M34: Ejemplo; declarar dispersión y limitaciones | N34: =IF(OR(G34<0,J34<>"mm",K34="",L34=""),"REVISAR","OK") -> OK
A35: SSP1-2.6 | B35: 2041-2060 | C35: 2050 | D35: 4 | E35: Abril | F35: =INDEX('Hoja 2 - Histórico'!$P$8:$P$19,MATCH(D35,'Hoja 2 - Histórico'!$N$8:$N$19,0)) -> 154.97 | G35: 156.5 | H35: =G35-F35 -> 1.53 | I35: =IF(F35=0,"",(G35-F35)/F35) -> 0.0098728786 | J35: mm | K35: Conjunto demostrativo | L35: Sustituir por IDEAM/CMIP6 | M35: Ejemplo; declarar dispersión y limitaciones | N35: =IF(OR(G35<0,J35<>"mm",K35="",L35=""),"REVISAR","OK") -> OK
... A45: SSP1-2.6 | B45: 2061-2080 | C45: 2070 | D45: 2 | E45: Febrero | F45: =INDEX('Hoja 2 - Histórico'!$P$8:$P$19,MATCH(D45,'Hoja 2 - Histórico'!$N$8:$N$19,0)) -> 75.066667 | G45: 74.3 | H45: =G45-F45 -> -0.76666667 | I45: =IF(F45=0,"",(G45-F45)/F45) -> -0.010213144 | J45: mm | K45: Conjunto demostrativo | L45: Sustituir por IDEAM/CMIP6 | M45: Ejemplo; declarar dispersión y limitaciones | N45: =IF(OR(G45<0,J45<>"mm",K45="",L45=""),"REVISAR","OK") -> OK
A46: SSP1-2.6 | B46: 2061-2080 | C46: 2070 | D46: 3 | E46: Marzo | F46: =INDEX('Hoja 2 - Histórico'!$P$8:$P$19,MATCH(D46,'Hoja 2 - Histórico'!$N$8:$N$19,0)) -> 110.1 | G46: 109 | H46: =G46-F46 -> -1.1 | I46: =IF(F46=0,"",(G46-F46)/F46) -> -0.0099909173 | J46: mm | K46: Conjunto demostrativo | L46: Sustituir por IDEAM/CMIP6 | M46: Ejemplo; declarar dispersión y limitaciones | N46: =IF(OR(G46<0,J46<>"mm",K46="",L46=""),"REVISAR","OK") -> OK | P46: Interpretación: el escenario no es una predicción exacta. Compare horizontes equivalentes, observe magnitud y dirección del cambio, declare la incertidumbre y transfiera a la Hoja 4 únicamente series con unidad, escala, periodo y fuente compatibles.
A47: SSP1-2.6 | B47: 2061-2080 | C47: 2070 | D47: 4 | E47: Abril | F47: =INDEX('Hoja 2 - Histórico'!$P$8:$P$19,MATCH(D47,'Hoja 2 - Histórico'!$N$8:$N$19,0)) -> 154.97 | G47: 153.4 | H47: =G47-F47 -> -1.57 | I47: =IF(F47=0,"",(G47-F47)/F47) -> -0.010130993 | J47: mm | K47: Conjunto demostrativo | L47: Sustituir por IDEAM/CMIP6 | M47: Ejemplo; declarar dispersión y limitaciones | N47: =IF(OR(G47<0,J47<>"mm",K47="",L47=""),"REVISAR","OK") -> OK
A48: SSP1-2.6 | B48: 2061-2080 | C48: 2070 | D48: 5 | E48: Mayo | F48: =INDEX('Hoja 2 - Histórico'!$P$8:$P$19,MATCH(D48,'Hoja 2 - Histórico'!$N$8:$N$19,0)) -> 139.87333 | G48: 138.5 | H48: =G48-F48 -> -1.3733333 | I48: =IF(F48=0,"",(G48-F48)/F48) -> -0.0098184071 | J48: mm | K48: Conjunto demostrativo | L48: Sustituir por IDEAM/CMIP6 | M48: Ejemplo; declarar dispersión y limitaciones | N48: =IF(OR(G48<0,J48<>"mm",K48="",L48=""),"REVISAR","OK") -> OK
A49: SSP1-2.6 | B49: 2061-2080 | C49: 2070 | D49: 6 | E49: Junio | F49: =INDEX('Hoja 2 - Histórico'!$P$8:$P$19,MATCH(D49,'Hoja 2 - Histórico'!$N$8:$N$19,0)) -> 84.956667 | G49: 84.1 | H49: =G49-F49 -> -0.85666667 | I49: =IF(F49=0,"",(G49-F49)/F49) -> -0.010083572 | J49: mm | K49: Conjunto demostrativo | L49: Sustituir por IDEAM/CMIP6 | M49: Ejemplo; declarar dispersión y limitaciones | N49: =IF(OR(G49<0,J49<>"mm",K49="",L49=""),"REVISAR","OK") -> OK
A50: SSP1-2.6 | B50: 2061-2080 | C50: 2070 | D50: 7 | E50: Julio | F50: =INDEX('Hoja 2 - Histórico'!$P$8:$P$19,MATCH(D50,'Hoja 2 - Histórico'!$N$8:$N$19,0)) -> 70.03 | G50: 69.3 | H50: =G50-F50 -> -0.73 | I50: =IF(F50=0,"",(G50-F50)/F50) -> -0.010424104 | J50: mm | K50: Conjunto demostrativo | L50: Sustituir por IDEAM/CMIP6 | M50: Ejemplo; declarar dispersión y limitaciones | N50: =IF(OR(G50<0,J50<>"mm",K50="",L50=""),"REVISAR","OK") -> OK
A51: SSP1-2.6 | B51: 2061-2080 | C51: 2070 | D51: 8 | E51: Agosto | F51: =INDEX('Hoja 2 - Histórico'!$P$8:$P$19,MATCH(D51,'Hoja 2 - Histórico'!$N$8:$N$19,0)) -> 75.036667 | G51: 74.3 | H51: =G51-F51 -> -0.73666667 | I51: =IF(F51=0,"",(G51-F51)/F51) -> -0.0098174226 | J51: mm | K51: Conjunto demostrativo | L51: Sustituir por IDEAM/CMIP6 | M51: Ejemplo; declarar dispersión y limitaciones | N51: =IF(OR(G51<0,J51<>"mm",K51="",L51=""),"REVISAR","OK") -> OK
...
